Workbook

Sheet P&L
A1: date | B1: revenue | C1: cogs | D1: gross_profit | E1: opex | F1: ebitda | G1: depreciation | H1: interest | I1: pre_tax_profit | J1: tax | K1: net_income | L1: capex | M1: cash_flow | N1: closing_cash | O1: opening_cash | P1: tax_loss_crfwd | Q1: dta | R1: cash_tax | S1: deferred_tax
A2: 44927 | B2: 0 | C2: =tblPL[[#This Row],[revenue]]*Assumptions!$B$4 -> 0 | D2: =tblPL[[#This Row],[revenue]]-tblPL[[#This Row],[cogs]] -> 0 | E2: =Assumptions!$B$8+tblPL[[#This Row],[revenue]]*Assumptions!$B$5 -> 6000 | F2: =tblPL[[#This Row],[gross_profit]]-tblPL[[#This Row],[opex]] -> -6000 | G2: =Assumptions!$B$9 -> 1500 | H2: =Assumptions!$B$10 -> 900 | I2: =tblPL[[#This Row],[ebitda]]-tblPL[[#This Row],[depreciation]]-tblPL[[#This Row],[interest]] -> -8400 | J2: =tblPL[[#This Row],[cash_tax]]+tblPL[[#This Row],[deferred_tax]] -> -2100 | K2: =tblPL[[#This Row],[pre_tax_profit]]-tblPL[[#This Row],[tax]] -> -6300 | L2: =IF(MONTH(tblPL[[#This Row],[date]])=1,Assumptions!$B$11,Assumptions!$B$12) -> 18000 | M2: =tblPL[[#This Row],[net_income]]+tblPL[[#This Row],[depreciation]]-tblPL[[#This Row],[capex]]+tblPL[[#This Row],[deferred_tax]] -> -24900 | N2: =tblPL[[#This Row],[opening_cash]]+tblPL[[#This Row],[cash_flow]] -> 75100 | O2: =Assumptions!$B$13 -> 100000 | P2: =MAX(0,Assumptions!$B$14-tblPL[[#This Row],[pre_tax_profit]]) -> 8400 | Q2: =tblPL[[#This Row],[tax_loss_crfwd]]*Assumptions!$B$6 -> 2100 | R2: =MAX(0,tblPL[[#This Row],[pre_tax_profit]]-Assumptions!$B$14)*Assumptions!$B$6 -> 0 | S2: =Assumptions!$B$14*Assumptions!$B$6-tblPL[[#This Row],[dta]] -> -2100
A3: 44958 | B3: 520.48 | C3: =tblPL[[#This Row],[revenue]]*Assumptions!$B$4 -> 166.5536 | D3: =tblPL[[#This Row],[revenue]]-tblPL[[#This Row],[cogs]] -> 353.9264 | E3: =Assumptions!$B$8+tblPL[[#This Row],[revenue]]*Assumptions!$B$5 -> 6093.6864 | F3: =tblPL[[#This Row],[gross_profit]]-tblPL[[#This Row],[opex]] -> -5739.76 | G3: =Assumptions!$B$9 -> 1500 | H3: =Assumptions!$B$10 -> 900 | I3: =tblPL[[#This Row],[ebitda]]-tblPL[[#This Row],[depreciation]]-tblPL[[#This Row],[interest]] -> -8139.76 | J3: =tblPL[[#This Row],[cash_tax]]+tblPL[[#This Row],[deferred_tax]] -> -2034.94 | K3: =tblPL[[#This Row],[pre_tax_profit]]-tblPL[[#This Row],[tax]] -> -6104.82 | L3: =IF(MONTH(tblPL[[#This Row],[date]])=1,Assumptions!$B$11,Assumptions!$B$12) -> 3500 | M3: =tblPL[[#This Row],[net_income]]+tblPL[[#This Row],[depreciation]]-tblPL[[#This Row],[capex]]+tblPL[[#This Row],[deferred_tax]] -> -10139.76 | N3: =tblPL[[#This Row],[opening_cash]]+tblPL[[#This Row],[cash_flow]] -> 64960.24 | O3: =N2 -> 75100 | P3: =MAX(0,P2-tblPL[[#This Row],[pre_tax_profit]]) -> 16539.76 | Q3: =tblPL[[#This Row],[tax_loss_crfwd]]*Assumptions!$B$6 -> 4134.94 | R3: =MAX(0,tblPL[[#This Row],[pre_tax_profit]]-P2)*Assumptions!$B$6 -> 0 | S3: =Q2-tblPL[[#This Row],[dta]] -> -2034.94
A4: 44986 | B4: 1248.32 | C4: =tblPL[[#This Row],[revenue]]*Assumptions!$B$4 -> 399.4624 | D4: =tblPL[[#This Row],[revenue]]-tblPL[[#This Row],[cogs]] -> 848.8576 | E4: =Assumptions!$B$8+tblPL[[#This Row],[revenue]]*Assumptions!$B$5 -> 6224.6976 | F4: =tblPL[[#This Row],[gross_profit]]-tblPL[[#This Row],[opex]] -> -5375.84 | G4: =Assumptions!$B$9 -> 1500 | H4: =Assumptions!$B$10 -> 900 | I4: =tblPL[[#This Row],[ebitda]]-tblPL[[#This Row],[depreciation]]-tblPL[[#This Row],[interest]] -> -7775.84 | J4: =tblPL[[#This Row],[cash_tax]]+tblPL[[#This Row],[deferred_tax]] -> -1943.96 | K4: =tblPL[[#This Row],[pre_tax_profit]]-tblPL[[#This Row],[tax]] -> -5831.88 | L4: =IF(MONTH(tblPL[[#This Row],[date]])=1,Assumptions!$B$11,Assumptions!$B$12) -> 3500 | M4: =tblPL[[#This Row],[net_income]]+tblPL[[#This Row],[depreciation]]-tblPL[[#This Row],[capex]]+tblPL[[#This Row],[deferred_tax]] -> -9775.84 | N4: =tblPL[[#This Row],[opening_cash]]+tblPL[[#This Row],[cash_flow]] -> 55184.4 | O4: =N3 -> 64960.24 | P4: =MAX(0,P3-tblPL[[#This Row],[pre_tax_profit]]) -> 24315.6 | Q4: =tblPL[[#This Row],[tax_loss_crfwd]]*Assumptions!$B$6 -> 6078.9 | R4: =MAX(0,tblPL[[#This Row],[pre_tax_profit]]-P3)*Assumptions!$B$6 -> 0 | S4: =Q3-tblPL[[#This Row],[dta]] -> -1943.96
A5: 45017 | B5: 2187.64 | C5: =tblPL[[#This Row],[revenue]]*Assumptions!$B$4 -> 700.0448 | D5: =tblPL[[#This Row],[revenue]]-tblPL[[#This Row],[cogs]] -> 1487.5952 | E5: =Assumptions!$B$8+tblPL[[#This Row],[revenue]]*Assumptions!$B$5 -> 6393.7752 | F5: =tblPL[[#This Row],[gross_profit]]-tblPL[[#This Row],[opex]] -> -4906.18 | G5: =Assumptions!$B$9 -> 1500 | H5: =Assumptions!$B$10 -> 900 | I5: =tblPL[[#This Row],[ebitda]]-tblPL[[#This Row],[depreciation]]-tblPL[[#This Row],[interest]] -> -7306.18 | J5: =tblPL[[#This Row],[cash_tax]]+tblPL[[#This Row],[deferred_tax]] -> -1826.545 | K5: =tblPL[[#This Row],[pre_tax_profit]]-tblPL[[#This Row],[tax]] -> -5479.635 | L5: =IF(MONTH(tblPL[[#This Row],[date]])=1,Assumptions!$B$11,Assumptions!$B$12) -> 3500 | M5: =tblPL[[#This Row],[net_income]]+tblPL[[#This Row],[depreciation]]-tblPL[[#This Row],[capex]]+tblPL[[#This Row],[deferred_tax]] -> -9306.18 | N5: =tblPL[[#This Row],[opening_cash]]+tblPL[[#This Row],[cash_flow]] -> 45878.22 | O5: =N4 -> 55184.4 | P5: =MAX(0,P4-tblPL[[#This Row],[pre_tax_profit]]) -> 31621.78 | Q5: =tblPL[[#This Row],[tax_loss_crfwd]]*Assumptions!$B$6 -> 7905.445 | R5: =MAX(0,tblPL[[#This Row],[pre_tax_profit]]-P4)*Assumptions!$B$6 -> 0 | S5: =Q4-tblPL[[#This Row],[dta]] -> -1826.545
A6: 45047 | B6: 3121.8 | C6: =tblPL[[#This Row],[revenue]]*Assumptions!$B$4 -> 998.976 | D6: =tblPL[[#This Row],[revenue]]-tblPL[[#This Row],[cogs]] -> 2122.824 | E6: =Assumptions!$B$8+tblPL[[#This Row],[revenue]]*Assumptions!$B$5 -> 6561.924 | F6: =tblPL[[#This Row],[gross_profit]]-tblPL[[#This Row],[opex]] -> -4439.1 | G6: =Assumptions!$B$9 -> 1500 | H6: =Assumptions!$B$10 -> 900 | I6: =tblPL[[#This Row],[ebitda]]-tblPL[[#This Row],[depreciation]]-tblPL[[#This Row],[interest]] -> -6839.1 | J6: =tblPL[[#This Row],[cash_tax]]+tblPL[[#This Row],[deferred_tax]] -> -1709.775 | K6: =tblPL[[#This Row],[pre_tax_profit]]-tblPL[[#This Row],[tax]] -> -5129.325 | L6: =IF(MONTH(tblPL[[#This Row],[date]])=1,Assumptions!$B$11,Assumptions!$B$12) -> 3500 | M6: =tblPL[[#This Row],[net_income]]+tblPL[[#This Row],[depreciation]]-tblPL[[#This Row],[capex]]+tblPL[[#This Row],[deferred_tax]] -> -8839.1 | N6: =tblPL[[#This Row],[opening_cash]]+tblPL[[#This Row],[cash_flow]] -> 37039.12 | O6: =N5 -> 45878.22 | P6: =MAX(0,P5-tblPL[[#This Row],[pre_tax_profit]]) -> 38460.88 | Q6: =tblPL[[#This Row],[tax_loss_crfwd]]*Assumptions!$B$6 -> 9615.22 | R6: =MAX(0,tblPL[[#This Row],[pre_tax_profit]]-P5)*Assumptions!$B$6 -> 0 | S6: =Q5-tblPL[[#This Row],[dta]] -> -1709.775
A7: 45078 | B7: 3930.56 | C7: =tblPL[[#This Row],[revenue]]*Assumptions!$B$4 -> 1257.7792 | D7: =tblPL[[#This Row],[revenue]]-tblPL[[#This Row],[cogs]] -> 2672.7808 | E7: =Assumptions!$B$8+tblPL[[#This Row],[revenue]]*Assumptions!$B$5 -> 6707.5008 | F7: =tblPL[[#This Row],[gross_profit]]-tblPL[[#This Row],[opex]] -> -4034.72 | G7: =Assumptions!$B$9 -> 1500 | H7: =Assumptions!$B$10 -> 900 | I7: =tblPL[[#This Row],[ebitda]]-tblPL[[#This Row],[depreciation]]-tblPL[[#This Row],[interest]] -> -6434.72 | J7: =tblPL[[#This Row],[cash_tax]]+tblPL[[#This Row],[deferred_tax]] -> -1608.68 | K7: =tblPL[[#This Row],[pre_tax_profit]]-tblPL[[#This Row],[tax]] -> -4826.04 | L7: =IF(MONTH(tblPL[[#This Row],[date]])=1,Assumptions!$B$11,Assumptions!$B$12) -> 3500 | M7: =tblPL[[#This Row],[net_income]]+tblPL[[#This Row],[depreciation]]-tblPL[[#This Row],[capex]]+tblPL[[#This Row],[deferred_tax]] -> -8434.72 | N7: =tblPL[[#This Row],[opening_cash]]+tblPL[[#This Row],[cash_flow]] -> 28604.4 | O7: =N6 -> 37039.12 | P7: =MAX(0,P6-tblPL[[#This Row],[pre_tax_profit]]) -> 44895.6 | Q7: =tblPL[[#This Row],[tax_loss_crfwd]]*Assumptions!$B$6 -> 11223.9 | R7: =MAX(0,tblPL[[#This Row],[pre_tax_profit]]-P6)*Assumptions!$B$6 -> 0 | S7: =Q6-tblPL[[#This Row],[dta]] -> -1608.68
A8: 45108 | B8: 4864.25 | C8: =tblPL[[#This Row],[revenue]]*Assumptions!$B$4 -> 1556.56 | D8: =tblPL[[#This Row],[revenue]]-tblPL[[#This Row],[cogs]] -> 3307.69 | E8: =Assumptions!$B$8+tblPL[[#This Row],[revenue]]*Assumptions!$B$5 -> 6875.565 | F8: =tblPL[[#This Row],[gross_profit]]-tblPL[[#This Row],[opex]] -> -3567.875 | G8: =Assumptions!$B$9 -> 1500 | H8: =Assumptions!$B$10 -> 900 | I8: =tblPL[[#This Row],[ebitda]]-tblPL[[#This Row],[depreciation]]-tblPL[[#This Row],[interest]] -> -5967.875 | J8: =tblPL[[#This Row],[cash_tax]]+tblPL[[#This Row],[deferred_tax]] -> -1491.9688 | K8: =tblPL[[#This Row],[pre_tax_profit]]-tblPL[[#This Row],[tax]] -> -4475.9062 | L8: =IF(MONTH(tblPL[[#This Row],[date]])=1,Assumptions!$B$11,Assumptions!$B$12) -> 3500 | M8: =tblPL[[#This Row],[net_income]]+tblPL[[#This Row],[depreciation]]-tblPL[[#This Row],[capex]]+tblPL[[#This Row],[deferred_tax]] -> -7967.875 | N8: =tblPL[[#This Row],[opening_cash]]+tblPL[[#This Row],[cash_flow]] -> 20636.525 | O8: =N7 -> 28604.4 | P8: =MAX(0,P7-tblPL[[#This Row],[pre_tax_profit]]) -> 50863.475 | Q8: =tblPL[[#This Row],[tax_loss_crfwd]]*Assumptions!$B$6 -> 12715.869 | R8: =MAX(0,tblPL[[#This Row],[pre_tax_profit]]-P7)*Assumptions!$B$6 -> 0 | S8: =Q7-tblPL[[#This Row],[dta]] -> -1491.9688
A9: 45139 | B9: 4932.76 | C9: =tblPL[[#This Row],[revenue]]*Assumptions!$B$4 -> 1578.4832 | D9: =tblPL[[#This Row],[revenue]]-tblPL[[#This Row],[cogs]] -> 3354.2768 | E9: =Assumptions!$B$8+tblPL[[#This Row],[revenue]]*Assumptions!$B$5 -> 6887.8968 | F9: =tblPL[[#This Row],[gross_profit]]-tblPL[[#This Row],[opex]] -> -3533.62 | G9: =Assumptions!$B$9 -> 1500 | H9: =Assumptions!$B$10 -> 900 | I9: =tblPL[[#This Row],[ebitda]]-tblPL[[#This Row],[depreciation]]-tblPL[[#This Row],[interest]] -> -5933.62 | J9: =tblPL[[#This Row],[cash_tax]]+tblPL[[#This Row],[deferred_tax]] -> -1483.405 | K9: =tblPL[[#This Row],[pre_tax_profit]]-tblPL[[#This Row],[tax]] -> -4450.215 | L9: =IF(MONTH(tblPL[[#This Row],[date]])=1,Assumptions!$B$11,Assumptions!$B$12) -> 3500 | M9: =tblPL[[#This Row],[net_income]]+tblPL[[#This Row],[depreciation]]-tblPL[[#This Row],[capex]]+tblPL[[#This Row],[deferred_tax]] -> -7933.62 | N9: =tblPL[[#This Row],[opening_cash]]+tblPL[[#This Row],[cash_flow]] -> 12702.905 | O9: =N8 -> 20636.525 | P9: =MAX(0,P8-tblPL[[#This Row],[pre_tax_profit]]) -> 56797.095 | Q9: =tblPL[[#This Row],[tax_loss_crfwd]]*Assumptions!$B$6 -> 14199.274 | R9: =MAX(0,tblPL[[#This Row],[pre_tax_profit]]-P8)*Assumptions!$B$6 -> 0 | S9: =Q8-tblPL[[#This Row],[dta]] -> -1483.405
A10: 45170 | B10: 4454.32 | C10: =tblPL[[#This Row],[revenue]]*Assumptions!$B$4 -> 1425.3824 | D10: =tblPL[[#This Row],[revenue]]-tblPL[[#This Row],[cogs]] -> 3028.9376 | E10: =Assumptions!$B$8+tblPL[[#This Row],[revenue]]*Assumptions!$B$5 -> 6801.7776 | F10: =tblPL[[#This Row],[gross_profit]]-tblPL[[#This Row],[opex]] -> -3772.84 | G10: =Assumptions!$B$9 -> 1500 | H10: =Assumptions!$B$10 -> 900 | I10: =tblPL[[#This Row],[ebitda]]-tblPL[[#This Row],[depreciation]]-tblPL[[#This Row],[interest]] -> -6172.84 | J10: =tblPL[[#This Row],[cash_tax]]+tblPL[[#This Row],[deferred_tax]] -> -1543.21 | K10: =tblPL[[#This Row],[pre_tax_profit]]-tblPL[[#This Row],[tax]] -> -4629.63 | L10: =IF(MONTH(tblPL[[#This Row],[date]])=1,Assumptions!$B$11,Assumptions!$B$12) -> 3500 | M10: =tblPL[[#This Row],[net_income]]+tblPL[[#This Row],[depreciation]]-tblPL[[#This Row],[capex]]+tblPL[[#This Row],[deferred_tax]] -> -8172.84 | N10: =tblPL[[#This Row],[opening_cash]]+tblPL[[#This Row],[cash_flow]] -> 4530.065 | O10: =N9 -> 12702.905 | P10: =MAX(0,P9-tblPL[[#This Row],[pre_tax_profit]]) -> 62969.935 | Q10: =tblPL[[#This Row],[tax_loss_crfwd]]*Assumptions!$B$6 -> 15742.484 | R10: =MAX(0,tblPL[[#This Row],[pre_tax_profit]]-P9)*Assumptions!$B$6 -> 0 | S10: =Q9-tblPL[[#This Row],[dta]] -> -1543.21
A11: 45200 | B11: 4707.53 | C11: =tblPL[[#This Row],[revenue]]*Assumptions!$B$4 -> 1506.4096 | D11: =tblPL[[#This Row],[revenue]]-tblPL[[#This Row],[cogs]] -> 3201.1204 | E11: =Assumptions!$B$8+tblPL[[#This Row],[revenue]]*Assumptions!$B$5 -> 6847.3554 | F11: =tblPL[[#This Row],[gross_profit]]-tblPL[[#This Row],[opex]] -> -3646.235 | G11: =Assumptions!$B$9 -> 1500 | H11: =Assumptions!$B$10 -> 900 | I11: =tblPL[[#This Row],[ebitda]]-tblPL[[#This Row],[depreciation]]-tblPL[[#This Row],[interest]] -> -6046.235 | J11: =tblPL[[#This Row],[cash_tax]]+tblPL[[#This Row],[deferred_tax]] -> -1511.5588 | K11: =tblPL[[#This Row],[pre_tax_profit]]-tblPL[[#This Row],[tax]] -> -4534.6763 | L11: =IF(MONTH(tblPL[[#This Row],[date]])=1,Assumptions!$B$11,Assumptions!$B$12) -> 3500 | M11: =tblPL[[#This Row],[net_income]]+tblPL[[#This Row],[depreciation]]-tblPL[[#This Row],[capex]]+tblPL[[#This Row],[deferred_tax]] -> -8046.235 | N11: =tblPL[[#This Row],[opening_cash]]+tblPL[[#This Row],[cash_flow]] -> -3516.17 | O11: =N10 -> 4530.065 | P11: =MAX(0,P10-tblPL[[#This Row],[pre_tax_profit]]) -> 69016.17 | Q11: =tblPL[[#This Row],[tax_loss_crfwd]]*Assumptions!$B$6 -> 17254.042 | R11: =MAX(0,tblPL[[#This Row],[pre_tax_profit]]-P10)*Assumptions!$B$6 -> 0 | S11: =Q10-tblPL[[#This Row],[dta]] -> -1511.5588
A12: 45231 | B12: 8435.38 | C12: =tblPL[[#This Row],[revenue]]*Assumptions!$B$4 -> 2699.3216 | D12: =tblPL[[#This Row],[revenue]]-tblPL[[#This Row],[cogs]] -> 5736.0584 | E12: =Assumptions!$B$8+tblPL[[#This Row],[revenue]]*Assumptions!$B$5 -> 7518.3684 | F12: =tblPL[[#This Row],[gross_profit]]-tblPL[[#This Row],[opex]] -> -1782.31 | G12: =Assumptions!$B$9 -> 1500 | H12: =Assumptions!$B$10 -> 900 | I12: =tblPL[[#This Row],[ebitda]]-tblPL[[#This Row],[depreciation]]-tblPL[[#This Row],[interest]] -> -4182.31 | J12: =tblPL[[#This Row],[cash_tax]]+tblPL[[#This Row],[deferred_tax]] -> -1045.5775 | K12: =tblPL[[#This Row],[pre_tax_profit]]-tblPL[[#This Row],[tax]] -> -3136.7325 | L12: =IF(MONTH(tblPL[[#This Row],[date]])=1,Assumptions!$B$11,Assumptions!$B$12) -> 3500 | M12: =tblPL[[#This Row],[net_income]]+tblPL[[#This Row],[depreciation]]-tblPL[[#This Row],[capex]]+tblPL[[#This Row],[deferred_tax]] -> -6182.31 | N12: =tblPL[[#This Row],[opening_cash]]+tblPL[[#This Row],[cash_flow]] -> -9698.48 | O12: =N11 -> -3516.17 | P12: =MAX(0,P11-tblPL[[#This Row],[pre_tax_profit]]) -> 73198.48 | Q12: =tblPL[[#This Row],[tax_loss_crfwd]]*Assumptions!$B$6 -> 18299.62 | R12: =MAX(0,tblPL[[#This Row],[pre_tax_profit]]-P11)*Assumptions!$B$6 -> 0 | S12: =Q11-tblPL[[#This Row],[dta]] -> -1045.5775
A13: 45261 | B13: 6872.47 | C13: =tblPL[[#This Row],[revenue]]*Assumptions!$B$4 -> 2199.1904 | D13: =tblPL[[#This Row],[revenue]]-tblPL[[#This Row],[cogs]] -> 4673.2796 | E13: =Assumptions!$B$8+tblPL[[#This Row],[revenue]]*Assumptions!$B$5 -> 7237.0446 | F13: =tblPL[[#This Row],[gross_profit]]-tblPL[[#This Row],[opex]] -> -2563.765 | G13: =Assumptions!$B$9 -> 1500 | H13: =Assumptions!$B$10 -> 900 | I13: =tblPL[[#This Row],[ebitda]]-tblPL[[#This Row],[depreciation]]-tblPL[[#This Row],[interest]] -> -4963.765 | J13: =tblPL[[#This Row],[cash_tax]]+tblPL[[#This Row],[deferred_tax]] -> -1240.9412 | K13: =tblPL[[#This Row],[pre_tax_profit]]-tblPL[[#This Row],[tax]] -> -3722.8238 | L13: =IF(MONTH(tblPL[[#This Row],[date]])=1,Assumptions!$B$11,Assumptions!$B$12) -> 3500 | M13: =tblPL[[#This Row],[net_income]]+tblPL[[#This Row],[depreciation]]-tblPL[[#This Row],[capex]]+tblPL[[#This Row],[deferred_tax]] -> -6963.765 | N13: =tblPL[[#This Row],[opening_cash]]+tblPL[[#This Row],[cash_flow]] -> -16662.245 | O13: =N12 -> -9698.48 | P13: =MAX(0,P12-tblPL[[#This Row],[pre_tax_profit]]) -> 78162.245 | Q13: =tblPL[[#This Row],[tax_loss_crfwd]]*Assumptions!$B$6 -> 19540.561 | R13: =MAX(0,tblPL[[#This Row],[pre_tax_profit]]-P12)*Assumptions!$B$6 -> 0 | S13: =Q12-tblPL[[#This Row],[dta]] -> -1240.9412
A14: 45292 | B14: 8692.13 | C14: =tblPL[[#This Row],[revenue]]*Assumptions!$B$4 -> 2781.4816 | D14: =tblPL[[#This Row],[revenue]]-tblPL[[#This Row],[cogs]] -> 5910.6484 | E14: =Assumptions!$B$8+tblPL[[#This Row],[revenue]]*Assumptions!$B$5 -> 7564.5834 | F14: =tblPL[[#This Row],[gross_profit]]-tblPL[[#This Row],[opex]] -> -1653.935 | G14: =Assumptions!$B$9 -> 1500 | H14: =Assumptions!$B$10 -> 900 | I14: =tblPL[[#This Row],[ebitda]]-tblPL[[#This Row],[depreciation]]-tblPL[[#This Row],[interest]] -> -4053.935 | J14: =tblPL[[#This Row],[cash_tax]]+tblPL[[#This Row],[deferred_tax]] -> -1013.4837 | K14: =tblPL[[#This Row],[pre_tax_profit]]-tblPL[[#This Row],[tax]] -> -3040.4513 | L14: =IF(MONTH(tblPL[[#This Row],[date]])=1,Assumptions!$B$11,Assumptions!$B$12) -> 18000 | M14: =tblPL[[#This Row],[net_income]]+tblPL[[#This Row],[depreciation]]-tblPL[[#This Row],[capex]]+tblPL[[#This Row],[deferred_tax]] -> -20553.935 | N14: =tblPL[[#This Row],[opening_cash]]+tblPL[[#This Row],[cash_flow]] -> -37216.18 | O14: =N13 -> -16662.245 | P14: =MAX(0,P13-tblPL[[#This Row],[pre_tax_profit]]) -> 82216.18 | Q14: =tblPL[[#This Row],[tax_loss_crfwd]]*Assumptions!$B$6 -> 20554.045 | R14: =MAX(0,tblPL[[#This Row],[pre_tax_profit]]-P13)*Assumptions!$B$6 -> 0 | S14: =Q13-tblPL[[#This Row],[dta]] -> -1013.4837
... A38: 46023 | B38: 187.32 | C38: =tblPL[[#This Row],[revenue]]*Assumptions!$B$4 -> 59.9424 | D38: =tblPL[[#This Row],[revenue]]-tblPL[[#This Row],[cogs]] -> 127.3776 | E38: =Assumptions!$B$8+tblPL[[#This Row],[revenue]]*Assumptions!$B$5 -> 6033.7176 | F38: =tblPL[[#This Row],[gross_profit]]-tblPL[[#This Row],[opex]] -> -5906.34 | G38: =Assumptions!$B$9 -> 1500 | H38: =Assumptions!$B$10 -> 900 | I38: =tblPL[[#This Row],[ebitda]]-tblPL[[#This Row],[depreciation]]-tblPL[[#This Row],[interest]] -> -8306.34 | J38: =tblPL[[#This Row],[cash_tax]]+tblPL[[#This Row],[deferred_tax]] -> -2076.585 | K38: =tblPL[[#This Row],[pre_tax_profit]]-tblPL[[#This Row],[tax]] -> -6229.755 | L38: =IF(MONTH(tblPL[[#This Row],[date]])=1,Assumptions!$B$11,Assumptions!$B$12) -> 18000 | M38: =tblPL[[#This Row],[net_income]]+tblPL[[#This Row],[depreciation]]-tblPL[[#This Row],[capex]]+tblPL[[#This Row],[deferred_tax]] -> -24806.34 | N38: =tblPL[[#This Row],[opening_cash]]+tblPL[[#This Row],[cash_flow]] -> -123898.79 | O38: =N37 -> -99092.455 | P38: =MAX(0,P37-tblPL[[#This Row],[pre_tax_profit]]) -> 91898.795 | Q38: =tblPL[[#This Row],[tax_loss_crfwd]]*Assumptions!$B$6 -> 22974.699 | R38: =MAX(0,tblPL[[#This Row],[pre_tax_profit]]-P37)*Assumptions!$B$6 -> 0 | S38: =Q37-tblPL[[#This Row],[dta]] -> -2076.585

Sheet Assumptions
A1: assumption | B1: value | C1: notes
A2: price_growth_annual | B2: 0.04 | C2: Annual price escalation per subscriber
A3: unit_growth_annual | B3: 0.05 | C3: Annual growth in paying subscribers
A4: cogs_pct | B4: 0.32 | C4: Cost of goods sold as % of revenue
A5: opex_pct | B5: 0.18 | C5: Operating expenses as % of revenue
A6: tax_rate | B6: 0.25 | C6: Corporate tax rate
A7: wacc | B7: 0.09 | C7: Weighted average cost of capital
A8: fixed_opex_monthly | B8: 6000 | C8: Fixed monthly operating expenses (on top of opex_pct × revenue)
A9: depreciation_monthly | B9: 1500 | C9: Monthly depreciation charge
A10: interest_monthly | B10: 900 | C10: Monthly interest expense
A11: capex_january | B11: 18000 | C11: Capex in January of each year (annual spend)
A12: capex_monthly | B12: 3500 | C12: Capex in all non-January months
A13: opening_cash | B13: 100000 | C13: Opening cash balance in first model month
A14: opening_tax_loss_cf | B14: 0 | C14: Unused tax losses brought forward at model start

Sheet constants_audit
A1: Constants Audit – P&L
A2: Scan of 'P&L'!A1:N38 for hardcoded constants, fixes applied, and replacement formulas linked to Assumptions
A4: Summary (after fixes)
A5: Distinct constants found | B5: =COUNT(tblConstantsAudit[Detected constant]) -> 9
A6: Total constant occurrences (cells) | B6: =SUM(tblConstantsAudit[Cells using]) -> 260
A7: Formula cells in P&L now | B7: {=SUMPRODUCT(--_xlfn.ISFORMULA('P&L'!A2:S38))} -> 629
A8: Input cells left in P&L (date, revenue) | B8: =COUNT('P&L'!A2:S38)-B7 -> 74
A9: Top 3 most reused constants
A10: Rank | B10: Constant | C10: Suggested assumption | D10: Uses
A11: 1 | B11: {=INDEX(_xlfn.SORTBY(tblConstantsAudit[Detected constant],tblConstantsAudit[Cells using],-1),A11)} -> 0.32 | C11: {=INDEX(_xlfn.SORTBY(tblConstantsAudit[Suggested named assumption],tblConstantsAudit[Cells using],-1),A11)} -> cogs_pct | D11: {=INDEX(_xlfn.SORTBY(tblConstantsAudit[Cells using],tblConstantsAudit[Cells using],-1),A11)} -> 37
A12: 2 | B12: {=INDEX(_xlfn.SORTBY(tblConstantsAudit[Detected constant],tblConstantsAudit[Cells using],-1),A12)} -> 6000 | C12: {=INDEX(_xlfn.SORTBY(tblConstantsAudit[Suggested named assumption],tblConstantsAudit[Cells using],-1),A12)} -> fixed_opex_monthly | D12: {=INDEX(_xlfn.SORTBY(tblConstantsAudit[Cells using],tblConstantsAudit[Cells using],-1),A12)} -> 37
A13: 3 | B13: {=INDEX(_xlfn.SORTBY(tblConstantsAudit[Detected constant],tblConstantsAudit[Cells using],-1),A13)} -> 0.18 | C13: {=INDEX(_xlfn.SORTBY(tblConstantsAudit[Suggested named assumption],tblConstantsAudit[Cells using],-1),A13)} -> opex_pct | D13: {=INDEX(_xlfn.SORTBY(tblConstantsAudit[Cells using],tblConstantsAudit[Cells using],-1),A13)} -> 37
A14: =COUNTIF(tblConstantsAudit[Cells using],D11)&" constants are tied at "&D11&" uses; ties are shown in table order." -> 6 constants are tied at 37 uses; ties are shown in table order.
A15: tblConstantsAudit – detected constants and replacement formulas
A16: Cell range | B16: P&L column | C16: Original content | D16: Detected constant | E16: Suggested named assumption | F16: Assumptions cell | G16: Assumption value | H16: Fixed formula (live from P&L) | I16: Cells using | J16: Change note
A17: C2:C38 | B17: cogs | C17: Typed values (≈ revenue × 0.32) | D17: 0.32 | E17: cogs_pct | F17: Assumptions!B4 | G17: =Assumptions!$B$4 -> 0.32 | H17: =_xlfn.FORMULATEXT('P&L'!C2) -> =[@revenue]*Assumptions!$B$4 | I17: =ROWS('P&L'!C2:C38) -> 37 | J17: Converted to formula; rows 6 & 35 (off by ±1) corrected as a result
A18: E2:E38 | B18: opex | C18: Typed values (≈ 6,000 + revenue × 0.18) | D18: 6000 | E18: fixed_opex_monthly | F18: Assumptions!B8 | G18: =Assumptions!$B$8 -> 6000 | H18: =_xlfn.FORMULATEXT('P&L'!E2) -> =Assumptions!$B$8+[@revenue]*Assumptions!$B$5 | I18: =ROWS('P&L'!E2:E38) -> 37 | J18: Fix 2: rows 30, 34, 36, 37, 38 corrected to the audited formula
A19: E2:E38 | B19: opex | C19: Typed values (≈ 6,000 + revenue × 0.18) | D19: 0.18 | E19: opex_pct | F19: Assumptions!B5 | G19: =Assumptions!$B$5 -> 0.18 | H19: =_xlfn.FORMULATEXT('P&L'!E2) -> =Assumptions!$B$8+[@revenue]*Assumptions!$B$5 | I19: =ROWS('P&L'!E2:E38) -> 37 | J19: Fix 2 (as above)
A20: G2:G38 | B20: depreciation | C20: Typed 1,500 each month | D20: 1500 | E20: depreciation_monthly | F20: Assumptions!B9 | G20: =Assumptions!$B$9 -> 1500 | H20: =_xlfn.FORMULATEXT('P&L'!G2) -> =Assumptions!$B$9 | I20: =COUNTIF('P&L_original'!G2:G38,D20) -> 37 | J20: New assumption added
A21: H2:H38 | B21: interest | C21: Typed 900 each month | D21: 900 | E21: interest_monthly | F21: Assumptions!B10 | G21: =Assumptions!$B$10 -> 900 | H21: =_xlfn.FORMULATEXT('P&L'!H2) -> =Assumptions!$B$10 | I21: =COUNTIF('P&L_original'!H2:H38,D21) -> 37 | J21: New assumption added
A22: J2:J38 (was I) | B22: tax | C22: Typed values (25% of pre-tax profit only in rows 2–9) | D22: 0.25 | E22: tax_rate | F22: Assumptions!B6 | G22: =Assumptions!$B$6 -> 0.25 | H22: =_xlfn.FORMULATEXT('P&L'!J2) -> =[@[cash_tax]]+[@[deferred_tax]] | I22: =ROWS('P&L'!J2:J38) -> 37 | J22: Fix 1: 25% × pre-tax profit → superseded by Fix 4: tax = cash_tax + deferred_tax (loss carryforward)
A23: L2, L14, L26, L38 (was K) | B23: capex | C23: Typed 18,000 in January | D23: 18000 | E23: capex_january | F23: Assumptions!B11 | G23: =Assumptions!$B$11 -> 18000 | H23: =_xlfn.FORMULATEXT('P&L'!L2) -> =IF(MONTH([@date])=1,Assumptions!$B$11,Assumptions!$B$12) | I23: =COUNTIF('P&L_original'!K2:K38,D23) -> 4 | J23: New assumption added; picked by MONTH(date)=1
A24: L3:L38 (was K) | B24: capex | C24: Typed 3,500 in other months | D24: 3500 | E24: capex_monthly | F24: Assumptions!B12 | G24: =Assumptions!$B$12 -> 3500 | H24: =_xlfn.FORMULATEXT('P&L'!L3) -> =IF(MONTH([@date])=1,Assumptions!$B$11,Assumptions!$B$12) | I24: =COUNTIF('P&L_original'!K2:K38,D24) -> 33 | J24: New assumption added
A25: O2 (was N2) | B25: opening_cash | C25: Typed 100,000 (first month) | D25: 100000 | E25: opening_cash | F25: Assumptions!B13 | G25: =Assumptions!$B$13 -> 100000 | H25: =_xlfn.FORMULATEXT('P&L'!O2) -> =Assumptions!$B$13 | I25: =COUNTIF('P&L_original'!N2,D25) -> 1 | J25: New assumption added
A26: D2:D38 | B26: gross_profit | C26: Typed values (derived) | E26: (none – derived) | H26: =_xlfn.FORMULATEXT('P&L'!D2) -> =[@revenue]-[@cogs] | J26: Converted to formula
A27: F2:F38 | B27: ebitda | C27: Typed values (derived) | E27: (none – derived) | H27: =_xlfn.FORMULATEXT('P&L'!F2) -> =[@[gross_profit]]-[@opex] | J27: Converted to formula
A28: K2:K38 (was J) | B28: net_income | C28: Typed values (derived) | E28: (none – derived) | H28: =_xlfn.FORMULATEXT('P&L'!K2) -> =[@[pre_tax_profit]]-[@tax] | J28: Recalculated after Fix 1 and Fix 4
A29: M2:M38 (was L) | B29: cash_flow | C29: Typed values (≈ net_income − capex) | E29: (none – derived) | H29: =_xlfn.FORMULATEXT('P&L'!M2) -> =[@[net_income]]+[@depreciation]-[@capex]+[@[deferred_tax]] | J29: Fix 3: net_income + depreciation − capex → Fix 5: + deferred_tax (non-cash)
A30: N2:N38 (was M) | B30: closing_cash | C30: Typed values (derived) | E30: (none – derived) | H30: =_xlfn.FORMULATEXT('P&L'!N2) -> =[@[opening_cash]]+[@[cash_flow]] | J30: Converted to formula; recalculates after Fix 3
A31: O3:O38 (was N) | B31: opening_cash | C31: Typed values (prior closing) | E31: (none – derived) | H31: =_xlfn.FORMULATEXT('P&L'!O3) -> =N2 | J31: Links to prior month closing_cash
A32: I2:I38 | B32: pre_tax_profit | C32: New column (Fix 4) | E32: (none – derived) | H32: =_xlfn.FORMULATEXT('P&L'!I2) -> =[@ebitda]-[@depreciation]-[@interest] | J32: Fix 4: ebitda − depreciation − interest
A33: P2:P38 | B33: tax_loss_crfwd | C33: New column (Fix 4) | E33: opening_tax_loss_cf | F33: Assumptions!B14 | G33: =Assumptions!$B$14 -> 0 | H33: =_xlfn.FORMULATEXT('P&L'!P3) -> =MAX(0,P2-[@[pre_tax_profit]]) | J33: Fix 4: MAX(0, prior c/f − pre-tax profit). P2 starts from opening_tax_loss_cf (new assumption, 0)
A34: Q2:Q38 | B34: dta | C34: New column (Fix 4) | E34: tax_rate | F34: Assumptions!B6 | G34: =Assumptions!$B$6 -> 0.25 | H34: =_xlfn.FORMULATEXT('P&L'!Q2) -> =[@[tax_loss_crfwd]]*Assumptions!$B$6 | J34: Fix 4: tax_loss_crfwd × tax_rate
A35: R2:R38 | B35: cash_tax | C35: New column (Fix 4) | E35: tax_rate | F35: Assumptions!B6 | G35: =Assumptions!$B$6 -> 0.25 | H35: =_xlfn.FORMULATEXT('P&L'!R3) -> =MAX(0,[@[pre_tax_profit]]-P2)*Assumptions!$B$6 | J35: Fix 4: (pre-tax profit − losses used) × tax_rate, never below 0
A36: S2:S38 | B36: deferred_tax | C36: New column (Fix 4) | E36: (none – derived) | H36: =_xlfn.FORMULATEXT('P&L'!S3) -> =Q2-[@dta] | J36: Fix 4: drop in DTA (negative = tax benefit in loss months)
A38: Change log – fixes applied (P&L now vs P&L_original snapshot, tolerance ±0.011)
A39: Fix | B39: P&L range | C39: Description | D39: Rows changed | E39: Original total | F39: New total | G39: Difference
A40: Fix 1 – tax | B40: J2:J38 (was I) | C40: tax = 25% × pre-tax profit on all rows – superseded by Fix 4 (same total tax expense) | D40: {=SUMPRODUCT(--(ABS('P&L'!J2:J38-'P&L_original'!I2:I38)>0.011))} -> 30 | E40: =SUM('P&L_original'!I2:I38) -> -28429.95 | F40: =SUM('P&L'!J2:J38) -> -22974.699 | G40: =F40-E40 -> 5455.2513
A41: Fix 1 knock-on | B41: K2:K38 (was J) | C41: net_income recalculated | D41: {=SUMPRODUCT(--(ABS('P&L'!K2:K38-'P&L_original'!J2:J38)>0.011))} -> 32 | E41: =SUM('P&L_original'!J2:J38) -> -86272.21 | F41: =SUM('P&L'!K2:K38) -> -68924.096 | G41: =F41-E41 -> 17348.114
A42: Fix 2 – opex | B42: E2:E38 | C42: opex = fixed_opex_monthly + opex_pct × revenue | D42: {=SUMPRODUCT(--(ABS('P&L'!E2:E38-'P&L_original'!E2:E38)>0.011))} -> 5 | E42: =SUM('P&L_original'!E2:E38) -> 301114.48 | F42: =SUM('P&L'!E2:E38) -> 300804.43 | G42: =F42-E42 -> -310.0462
...

Sheet P&L_original
A1: date | B1: revenue | C1: cogs | D1: gross_profit | E1: opex | F1: ebitda | G1: depreciation | H1: interest | I1: tax | J1: net_income | K1: capex | L1: cash_flow | M1: closing_cash | N1: opening_cash | P1: Snapshot of P&L values before fixes (taken 2026-10-08). Do not edit – used by constants_audit.
A2: 44927 | B2: 0 | C2: 0 | D2: 0 | E2: 6000 | F2: -6000 | G2: 1500 | H2: 900 | I2: -2100 | J2: -6300 | K2: 18000 | L2: -24300 | M2: 75700 | N2: 100000
A3: 44958 | B3: 520.48 | C3: 166.55 | D3: 353.93 | E3: 6093.69 | F3: -5739.76 | G3: 1500 | H3: 900 | I3: -2034.94 | J3: -6104.82 | K3: 3500 | L3: -9604.82 | M3: 66095.18 | N3: 75700
A4: 44986 | B4: 1248.32 | C4: 399.46 | D4: 848.86 | E4: 6224.7 | F4: -5375.84 | G4: 1500 | H4: 900 | I4: -1943.96 | J4: -5831.88 | K4: 3500 | L4: -9331.88 | M4: 56763.3 | N4: 66095.18
A5: 45017 | B5: 2187.64 | C5: 700.04 | D5: 1487.6 | E5: 6393.78 | F5: -4906.18 | G5: 1500 | H5: 900 | I5: -1826.55 | J5: -5482.63 | K5: 3500 | L5: -8982.63 | M5: 47780.67 | N5: 56763.3
A6: 45047 | B6: 3121.8 | C6: 999.98 | D6: 2121.82 | E6: 6561.92 | F6: -4440.1 | G6: 1500 | H6: 900 | I6: -1710.03 | J6: -5130.13 | K6: 3500 | L6: -8630.13 | M6: 39150.54 | N6: 47780.67
A7: 45078 | B7: 3930.56 | C7: 1257.78 | D7: 2672.78 | E7: 6707.5 | F7: -4034.72 | G7: 1500 | H7: 900 | I7: -1608.69 | J7: -4826.03 | K7: 3500 | L7: -8326.03 | M7: 30824.51 | N7: 39150.54
A8: 45108 | B8: 4864.25 | C8: 1556.56 | D8: 3307.69 | E8: 6875.57 | F8: -3567.88 | G8: 1500 | H8: 900 | I8: -1491.97 | J8: -4475.85 | K8: 3500 | L8: -7975.85 | M8: 22848.66 | N8: 30824.51
A9: 45139 | B9: 4932.76 | C9: 1578.48 | D9: 3354.28 | E9: 6887.9 | F9: -3533.62 | G9: 1500 | H9: 900 | I9: -1483.41 | J9: -4450.21 | K9: 3500 | L9: -7950.21 | M9: 14898.45 | N9: 22848.66
A10: 45170 | B10: 4454.32 | C10: 1425.38 | D10: 3028.94 | E10: 6801.78 | F10: -3772.84 | G10: 1500 | H10: 900 | I10: -1568.21 | J10: -4705.05 | K10: 3500 | L10: -8205.05 | M10: 6693.4 | N10: 14898.45
A11: 45200 | B11: 4707.53 | C11: 1506.41 | D11: 3201.12 | E11: 6847.36 | F11: -3646.24 | G11: 1500 | H11: 900 | I11: -1536.56 | J11: -4610.8 | K11: 3500 | L11: -8110.8 | M11: -1417.4 | N11: 6693.4
A12: 45231 | B12: 8435.38 | C12: 2699.32 | D12: 5736.06 | E12: 7518.37 | F12: -1782.31 | G12: 1500 | H12: 900 | I12: -1170.58 | J12: -3512.73 | K12: 3500 | L12: -7012.73 | M12: -8430.13 | N12: -1417.4
A13: 45261 | B13: 6872.47 | C13: 2199.19 | D13: 4673.28 | E13: 7237.04 | F13: -2563.76 | G13: 1500 | H13: 900 | I13: -1365.94 | J13: -4099.7 | K13: 3500 | L13: -7599.7 | M13: -16029.83 | N13: -8430.13
... A38: 46023 | B38: 187.32 | C38: 59.94 | D38: 127.38 | E38: 6033.74 | F38: -5906.36 | G38: 1500 | H38: 900 | I38: -2091.59 | J38: -6273.77 | K38: 18000 | L38: -24273.77 | M38: -156272.21 | N38: -131998.44
